Setting up a new session...
Traceback (most recent call last):
  File "/home/16amf8/anaconda3/envs/FER/lib/python3.7/site-packages/urllib3/connection.py", line 175, in _new_conn
    (self._dns_host, self.port), self.timeout, **extra_kw
  File "/home/16amf8/anaconda3/envs/FER/lib/python3.7/site-packages/urllib3/util/connection.py", line 96, in create_connection
    raise err
  File "/home/16amf8/anaconda3/envs/FER/lib/python3.7/site-packages/urllib3/util/connection.py", line 86, in create_connection
    sock.connect(sa)
ConnectionRefusedError: [Errno 111] Connection refused

During handling of the above exception, another exception occurred:

Traceback (most recent call last):
  File "/home/16amf8/anaconda3/envs/FER/lib/python3.7/site-packages/urllib3/connectionpool.py", line 706, in urlopen
    chunked=chunked,
  File "/home/16amf8/anaconda3/envs/FER/lib/python3.7/site-packages/urllib3/connectionpool.py", line 394, in _make_request
    conn.request(method, url, **httplib_request_kw)
  File "/home/16amf8/anaconda3/envs/FER/lib/python3.7/site-packages/urllib3/connection.py", line 239, in request
    super(HTTPConnection, self).request(method, url, body=body, headers=headers)
  File "/home/16amf8/anaconda3/envs/FER/lib/python3.7/http/client.py", line 1281, in request
    self._send_request(method, url, body, headers, encode_chunked)
  File "/home/16amf8/anaconda3/envs/FER/lib/python3.7/http/client.py", line 1327, in _send_request
    self.endheaders(body, encode_chunked=encode_chunked)
  File "/home/16amf8/anaconda3/envs/FER/lib/python3.7/http/client.py", line 1276, in endheaders
    self._send_output(message_body, encode_chunked=encode_chunked)
  File "/home/16amf8/anaconda3/envs/FER/lib/python3.7/http/client.py", line 1036, in _send_output
    self.send(msg)
  File "/home/16amf8/anaconda3/envs/FER/lib/python3.7/http/client.py", line 976, in send
    self.connect()
  File "/home/16amf8/anaconda3/envs/FER/lib/python3.7/site-packages/urllib3/connection.py", line 205, in connect
    conn = self._new_conn()
  File "/home/16amf8/anaconda3/envs/FER/lib/python3.7/site-packages/urllib3/connection.py", line 187, in _new_conn
    self, "Failed to establish a new connection: %s" % e
urllib3.exceptions.NewConnectionError: <urllib3.connection.HTTPConnection object at 0x7fa4fce3df10>: Failed to establish a new connection: [Errno 111] Connection refused

During handling of the above exception, another exception occurred:

Traceback (most recent call last):
  File "/home/16amf8/anaconda3/envs/FER/lib/python3.7/site-packages/requests/adapters.py", line 449, in send
    timeout=timeout
  File "/home/16amf8/anaconda3/envs/FER/lib/python3.7/site-packages/urllib3/connectionpool.py", line 756, in urlopen
    method, url, error=e, _pool=self, _stacktrace=sys.exc_info()[2]
  File "/home/16amf8/anaconda3/envs/FER/lib/python3.7/site-packages/urllib3/util/retry.py", line 574, in increment
    raise MaxRetryError(_pool, url, error or ResponseError(cause))
urllib3.exceptions.MaxRetryError: HTTPConnectionPool(host='localhost', port=8097): Max retries exceeded with url: /env/main (Caused by NewConnectionError('<urllib3.connection.HTTPConnection object at 0x7fa4fce3df10>: Failed to establish a new connection: [Errno 111] Connection refused'))

During handling of the above exception, another exception occurred:

Traceback (most recent call last):
  File "/home/16amf8/anaconda3/envs/FER/lib/python3.7/site-packages/visdom/__init__.py", line 711, in _send
    data=json.dumps(msg),
  File "/home/16amf8/anaconda3/envs/FER/lib/python3.7/site-packages/visdom/__init__.py", line 677, in _handle_post
    r = self.session.post(url, data=data)
  File "/home/16amf8/anaconda3/envs/FER/lib/python3.7/site-packages/requests/sessions.py", line 590, in post
    return self.request('POST', url, data=data, json=json, **kwargs)
  File "/home/16amf8/anaconda3/envs/FER/lib/python3.7/site-packages/requests/sessions.py", line 542, in request
    resp = self.send(prep, **send_kwargs)
  File "/home/16amf8/anaconda3/envs/FER/lib/python3.7/site-packages/requests/sessions.py", line 655, in send
    r = adapter.send(request, **kwargs)
  File "/home/16amf8/anaconda3/envs/FER/lib/python3.7/site-packages/requests/adapters.py", line 516, in send
    raise ConnectionError(e, request=request)
requests.exceptions.ConnectionError: HTTPConnectionPool(host='localhost', port=8097): Max retries exceeded with url: /env/main (Caused by NewConnectionError('<urllib3.connection.HTTPConnection object at 0x7fa4fce3df10>: Failed to establish a new connection: [Errno 111] Connection refused'))
[Errno 111] Connection refused
slurmstepd-sasquatch: error: *** JOB 6820 ON sasquatch CANCELLED AT 2021-12-01T21:03:21 ***
